<mujoco model="g1_29dof_inspire">
  <compiler angle="radian" meshdir="../meshes/unitree_meshes/" />

  <default>
    <default class="arm_motor">
      <joint damping="0.05" armature="0.01" frictionloss="0.2"/>
    </default>
    <default class="wrist_motor">
      <joint damping="0.05" armature="0.01" frictionloss="0.1"/>
    </default>
    <default class="visual">
      <geom contype="0" conaffinity="0" group="2" />
    </default>
    <default class="base_static">
        <geom condim="3" contype="1" conaffinity="2" group="1" />
    </default>
    <default class="left_arm_active">
        <geom condim="3" contype="2" conaffinity="3" group="1" friction="1 0.01 0.01" />
    </default>
    
  </default>



  <asset>
    <mesh name="pelvis" file="pelvis.STL" />
    <mesh name="pelvis_contour_link" file="pelvis_contour_link.STL" />
    <mesh name="left_hip_pitch_link" file="left_hip_pitch_link.STL" />
    <mesh name="left_hip_roll_link" file="left_hip_roll_link.STL" />
    <mesh name="left_hip_yaw_link" file="left_hip_yaw_link.STL" />
    <mesh name="left_knee_link" file="left_knee_link.STL" />
    <mesh name="left_ankle_pitch_link" file="left_ankle_pitch_link.STL" />
    <mesh name="left_ankle_roll_link" file="left_ankle_roll_link.STL" />
    <mesh name="right_hip_pitch_link" file="right_hip_pitch_link.STL" />
    <mesh name="right_hip_roll_link" file="right_hip_roll_link.STL" />
    <mesh name="right_hip_yaw_link" file="right_hip_yaw_link.STL" />
    <mesh name="right_knee_link" file="right_knee_link.STL" />
    <mesh name="right_ankle_pitch_link" file="right_ankle_pitch_link.STL" />
    <mesh name="right_ankle_roll_link" file="right_ankle_roll_link.STL" />
    <mesh name="waist_yaw_link" file="waist_yaw_link.STL" />
    <mesh name="waist_roll_link" file="waist_roll_link.STL" />
    <mesh name="logo_link" file="logo_link.STL" />
    <mesh name="head_link" file="head_link.STL" />
    <mesh name="waist_support_link" file="waist_support_link.STL" />

    <!-- left part -->
    <mesh name="left_shoulder_pitch_link" file="left_shoulder_pitch_link.STL" />
    <mesh name="left_shoulder_roll_link" file="left_shoulder_roll_link.STL" />
    <mesh name="left_shoulder_yaw_link" file="left_shoulder_yaw_link.STL" />
    <mesh name="left_elbow_link" file="left_elbow_link.STL" />
    <mesh name="left_wrist_roll_link" file="left_wrist_roll_link.STL" />
    <mesh name="left_wrist_pitch_link" file="left_wrist_pitch_link.STL" />
    <mesh name="left_wrist_yaw_link" file="left_wrist_yaw_link.STL" />
    <mesh name="torso_link" file="torso_link.STL" />
    <mesh name="inhand_base_link" file="Inspire_RH56DFTP/base_link.STL" />
    <mesh name="inhand_left_thumb_1" file="Inspire_RH56DFTP/left_thumb_1.STL" />
    <mesh name="inhand_left_thumb_2" file="Inspire_RH56DFTP/left_thumb_2.STL" />
    <mesh name="inhand_left_thumb_3" file="Inspire_RH56DFTP/left_thumb_3.STL" />
    <mesh name="inhand_left_thumb_4" file="Inspire_RH56DFTP/left_thumb_4.STL" />
    <mesh name="inhand_left_index_1" file="Inspire_RH56DFTP/left_index_1.STL" />
    <mesh name="inhand_left_index_2" file="Inspire_RH56DFTP/left_index_2.STL" />
    <mesh name="inhand_left_middle_1" file="Inspire_RH56DFTP/left_middle_1.STL" />
    <mesh name="inhand_left_middle_2" file="Inspire_RH56DFTP/left_middle_2.STL" />
    <mesh name="inhand_left_ring_1" file="Inspire_RH56DFTP/left_ring_1.STL" />
    <mesh name="inhand_left_ring_2" file="Inspire_RH56DFTP/left_ring_2.STL" />
    <mesh name="inhand_left_little_1" file="Inspire_RH56DFTP/left_little_1.STL" />
    <mesh name="inhand_left_little_2" file="Inspire_RH56DFTP/left_little_2.STL" />
    <!-- stop here -->

    <mesh name="right_shoulder_pitch_link" file="right_shoulder_pitch_link.STL" />
    <mesh name="right_shoulder_roll_link" file="right_shoulder_roll_link.STL" />
    <mesh name="right_shoulder_yaw_link" file="right_shoulder_yaw_link.STL" />
    <mesh name="right_elbow_link" file="right_elbow_link.STL" />
    <mesh name="right_wrist_roll_link" file="right_wrist_roll_link.STL" />
    <mesh name="right_wrist_pitch_link" file="right_wrist_pitch_link.STL" />
    <mesh name="right_wrist_yaw_link" file="right_wrist_yaw_link.STL" />
    <mesh name="right_rubber_hand" file="right_rubber_hand.STL" />

    <texture name="plane" type="2d" builtin="checker" rgb1=".1 .1 .1" rgb2=".9 .9 .9"
        width="64" height="64" mark="cross" markrgb=".8 .8 .8" />
    <material name="plane" reflectance="0.3" texture="plane" texrepeat="4 4" texuniform="true"/>
  </asset>

  <worldbody>
    <geom name="floor" pos="0 0 0" size="0 0 .25" type="plane" material="plane"
            condim="3" />
    <light directional="true" ambient=".3 .3 .3" pos="30 30 30" dir="0 -.5 -1"
        diffuse=".5 .5 .5" specular=".5 .5 .5" />

    <body name="pelvis" pos="0 0 0.793">
      <site name="imu" size="0.01" pos="0.0 0.0 0.0" />
      <inertial pos="0 0 -0.07605" quat="1 0 -0.000399148 0" mass="3.813"
        diaginertia="0.010549 0.0093089 0.0079184" />
      <geom type="mesh" contype="0" conaffinity="0" group="1" density="0" rgba="0.2 0.2 0.2 1"
        mesh="pelvis" />
      <geom type="mesh" contype="0" conaffinity="0" group="1" density="0" rgba="0.7 0.7 0.7 1"
        mesh="pelvis_contour_link" />
      <geom type="mesh" rgba="0.7 0.7 0.7 1" mesh="pelvis_contour_link" class="base_static"/>
      <body name="left_hip_pitch_link" pos="0 0.064452 -0.1027">
        <inertial pos="0.002741 0.047791 -0.02606" quat="0.954862 0.293964 0.0302556 0.030122"
          mass="1.35" diaginertia="0.00181517 0.00153422 0.00116212" />
        <geom type="mesh" contype="0" conaffinity="0" group="1" density="0" rgba="0.2 0.2 0.2 1"
          mesh="left_hip_pitch_link" />
        <geom type="mesh" rgba="0.2 0.2 0.2 1" mesh="left_hip_pitch_link" class="base_static"/>
        <body name="left_hip_roll_link" pos="0 0.052 -0.030465" quat="0.996179 0 -0.0873386 0">
          <inertial pos="0.029812 -0.001045 -0.087934"
            quat="0.977808 -1.97119e-05 0.205576 -0.0403793" mass="1.52"
            diaginertia="0.00254986 0.00241169 0.00148755" />
          <geom type="mesh" contype="0" conaffinity="0" group="1" density="0" rgba="0.7 0.7 0.7 1"
            mesh="left_hip_roll_link" />
          <geom type="mesh" rgba="0.7 0.7 0.7 1" mesh="left_hip_roll_link" class="base_static"/>
          <body name="left_hip_yaw_link" pos="0.025001 0 -0.12412">
            <inertial pos="-0.057709 -0.010981 -0.15078" quat="0.600598 0.15832 0.223482 0.751181"
              mass="1.702" diaginertia="0.00776166 0.00717575 0.00160139" />
            <geom type="mesh" contype="0" conaffinity="0" group="1" density="0" rgba="0.7 0.7 0.7 1"
              mesh="left_hip_yaw_link" />
            <geom type="mesh" rgba="0.7 0.7 0.7 1" mesh="left_hip_yaw_link" class="base_static"/>
            <body name="left_knee_link" pos="-0.078273 0.0021489 -0.17734"
              quat="0.996179 0 0.0873386 0">
              <inertial pos="0.005457 0.003964 -0.12074"
                quat="0.923418 -0.0327699 0.0158246 0.382067" mass="1.932"
                diaginertia="0.0113804 0.0112778 0.00146458" />
              <geom type="mesh" contype="0" conaffinity="0" group="1" density="0"
                rgba="0.7 0.7 0.7 1" mesh="left_knee_link" />
              <geom type="mesh" rgba="0.7 0.7 0.7 1" mesh="left_knee_link" class="base_static"/>
              <body name="left_ankle_pitch_link" pos="0 -9.4445e-05 -0.30001">
                <inertial pos="-0.007269 0 0.011137" quat="0.603053 0.369225 0.369225 0.603053"
                  mass="0.074" diaginertia="1.89e-05 1.40805e-05 6.9195e-06" />
                <geom type="mesh" contype="0" conaffinity="0" group="1" density="0"
                  rgba="0.7 0.7 0.7 1" mesh="left_ankle_pitch_link" />
                <geom type="mesh" rgba="0.7 0.7 0.7 1" mesh="left_ankle_pitch_link" class="base_static"/>
                <body name="left_ankle_roll_link" pos="0 0 -0.017558">
                  <inertial pos="0.026505 0 -0.016425"
                    quat="-0.000481092 0.728482 -0.000618967 0.685065" mass="0.608"
                    diaginertia="0.00167218 0.0016161 0.000217621" />
                  <geom type="mesh" contype="0" conaffinity="0" group="1" density="0"
                    rgba="0.2 0.2 0.2 1" mesh="left_ankle_roll_link" />
                  <geom size="0.005" pos="-0.05 0.025 -0.03" rgba="0.2 0.2 0.2 1" class="base_static"/>
                  <geom size="0.005" pos="-0.05 -0.025 -0.03" rgba="0.2 0.2 0.2 1" class="base_static"/>
                  <geom size="0.005" pos="0.12 0.03 -0.03" rgba="0.2 0.2 0.2 1" class="base_static"/>
                  <geom size="0.005" pos="0.12 -0.03 -0.03" rgba="0.2 0.2 0.2 1" class="base_static"/>
                </body>
              </body>
            </body>
          </body>
        </body>
      </body>
      <body name="right_hip_pitch_link" pos="0 -0.064452 -0.1027">
        <inertial pos="0.002741 -0.047791 -0.02606" quat="0.954862 -0.293964 0.0302556 -0.030122"
          mass="1.35" diaginertia="0.00181517 0.00153422 0.00116212" />
        <geom type="mesh" contype="0" conaffinity="0" group="1" density="0" rgba="0.2 0.2 0.2 1"
          mesh="right_hip_pitch_link" />
        <geom type="mesh" rgba="0.2 0.2 0.2 1" mesh="right_hip_pitch_link" class="base_static"/>
        <body name="right_hip_roll_link" pos="0 -0.052 -0.030465" quat="0.996179 0 -0.0873386 0">
          <inertial pos="0.029812 0.001045 -0.087934" quat="0.977808 1.97119e-05 0.205576 0.0403793"
            mass="1.52" diaginertia="0.00254986 0.00241169 0.00148755" />
          <geom type="mesh" contype="0" conaffinity="0" group="1" density="0" rgba="0.7 0.7 0.7 1"
            mesh="right_hip_roll_link" />
          <geom type="mesh" rgba="0.7 0.7 0.7 1" mesh="right_hip_roll_link" class="base_static"/>
          <body name="right_hip_yaw_link" pos="0.025001 0 -0.12412">
            <inertial pos="-0.057709 0.010981 -0.15078" quat="0.751181 0.223482 0.15832 0.600598"
              mass="1.702" diaginertia="0.00776166 0.00717575 0.00160139" />
            <geom type="mesh" contype="0" conaffinity="0" group="1" density="0" rgba="0.7 0.7 0.7 1"
              mesh="right_hip_yaw_link" />
            <geom type="mesh" rgba="0.7 0.7 0.7 1" mesh="right_hip_yaw_link" class="base_static"/>
            <body name="right_knee_link" pos="-0.078273 -0.0021489 -0.17734"
              quat="0.996179 0 0.0873386 0">
              <inertial pos="0.005457 -0.003964 -0.12074"
                quat="0.923439 0.0345276 0.0116333 -0.382012" mass="1.932"
                diaginertia="0.011374 0.0112843 0.00146452" />
              <geom type="mesh" contype="0" conaffinity="0" group="1" density="0"
                rgba="0.7 0.7 0.7 1" mesh="right_knee_link" />
              <geom type="mesh" rgba="0.7 0.7 0.7 1" mesh="right_knee_link" class="base_static"/>
              <body name="right_ankle_pitch_link" pos="0 9.4445e-05 -0.30001">
                <inertial pos="-0.007269 0 0.011137" quat="0.603053 0.369225 0.369225 0.603053"
                  mass="0.074" diaginertia="1.89e-05 1.40805e-05 6.9195e-06" />
                <geom type="mesh" contype="0" conaffinity="0" group="1" density="0"
                  rgba="0.7 0.7 0.7 1" mesh="right_ankle_pitch_link" />
                <geom type="mesh" rgba="0.7 0.7 0.7 1" mesh="right_ankle_pitch_link" class="base_static"/>
                <body name="right_ankle_roll_link" pos="0 0 -0.017558">
                  <inertial pos="0.026505 0 -0.016425"
                    quat="0.000481092 0.728482 0.000618967 0.685065" mass="0.608"
                    diaginertia="0.00167218 0.0016161 0.000217621" />
                  <geom type="mesh" contype="0" conaffinity="0" group="1" density="0"
                    rgba="0.2 0.2 0.2 1" mesh="right_ankle_roll_link" />
                  <geom size="0.005" pos="-0.05 0.025 -0.03" rgba="0.2 0.2 0.2 1" class="base_static"/>
                  <geom size="0.005" pos="-0.05 -0.025 -0.03" rgba="0.2 0.2 0.2 1" class="base_static"/>
                  <geom size="0.005" pos="0.12 0.03 -0.03" rgba="0.2 0.2 0.2 1" class="base_static"/>
                  <geom size="0.005" pos="0.12 -0.03 -0.03" rgba="0.2 0.2 0.2 1" class="base_static"/>
                </body>
              </body>
            </body>
          </body>
        </body>
      </body>
      <body name="waist_yaw_link">
        <inertial pos="0.003964 0 0.018769" quat="-0.0178291 0.628464 0.0282471 0.777121"
          mass="0.244" diaginertia="0.000158561 0.000124229 9.67669e-05" />
        <geom type="mesh" group="1" density="0" rgba="0.7 0.7 0.7 1"
          mesh="waist_yaw_link" class="base_static"/>
        <body name="waist_roll_link" pos="-0.0039635 0 0.035">
          <inertial pos="0 -0.000236 0.010111" quat="0.99979 0.020492 0 0" mass="0.047"
            diaginertia="7.515e-06 6.40206e-06 3.98394e-06" />
          <geom type="mesh" group="1" density="0" rgba="0.7 0.7 0.7 1"
            mesh="waist_roll_link" class="base_static"/>
          <body name="torso_link" pos="0 0 0.019">
            <inertial pos="0.00331658 0.000261533 0.179856" quat="0.999831 0.000376204 0.0179895 -0.00377704" mass="9.598" diaginertia="0.12407 0.111951 0.0325382" />
            
            <geom name="torso_collision" type="mesh" mesh="torso_link" class="base_static" rgba="0.7 0.7 0.7 1" />

            <geom name="logo_collision" pos="0.0039635 0 -0.054" quat="1 0 0 0" type="mesh" mesh="logo_link" class="base_static" rgba="0.2 0.2 0.2 1" />

            <geom name="head_collision" pos="0.0039635 0 -0.054" type="mesh" mesh="head_link" class="base_static" rgba="0.2 0.2 0.2 1" />

            <geom name="waist_support_collision" pos="0.0039635 0 -0.054" quat="1 0 0 0" type="mesh" mesh="waist_support_link" class="base_static" rgba="0.7 0.7 0.7 1" />
            <body name="left_shoulder_pitch_link" pos="0.0039563 0.10022 0.23778" quat="0.990264 0.139201 1.38722e-05 -9.86868e-05">
                <inertial pos="0 0.035892 -0.011628" quat="0.654152 0.0130458 -0.326267 0.68225"
                mass="0.718" diaginertia="0.000465864 0.000432842 0.000406394"/>
                <joint name="left_shoulder_pitch_joint" pos="0 0 0" axis="0 1 0"
                range="-3.0892 2.6704" actuatorfrcrange="-25 25" class="arm_motor" />
                <geom type="mesh" mesh="left_shoulder_pitch_link" class="visual" />
                <geom name="left_shoulder_pitch_link_collision" pos="0 0 0" quat="1.0 0.0 0.0 0.0" type="mesh" mesh="left_shoulder_pitch_link" class="left_arm_active" />

                <body name="left_shoulder_roll_link" pos="0 0.038 -0.013831" quat="0.9994 0.105 0 0">
                <inertial pos="-0.000227 0.00727 -0.063243" quat="0.701256 -0.0196223 -0.00710317 0.712604" mass="0.643" diaginertia="0.000691311 0.000618011 0.000388977" />
                <joint name="left_shoulder_roll_joint" pos="0 0 0" axis="1 0 0" range="-1.5882 2.2515" actuatorfrcrange="-25 25" class="arm_motor" />
                <geom type="mesh" mesh="left_shoulder_roll_link" class="visual" />
                <geom name="left_shoulder_roll_link_collision" pos="0 0 0" quat="1.0 0.0 0.0 0.0" type="mesh" mesh="left_shoulder_roll_link" class="left_arm_active" />


                <body name="left_shoulder_yaw_link" pos="0 0.00624 -0.1032">
                    <inertial pos="0.010773 -0.002949 -0.072009" quat="0.716879 -0.0964829 -0.0679942 0.687134" mass="0.734" diaginertia="0.00106187 0.00103217 0.000400661" />
                    <joint name="left_shoulder_yaw_joint" pos="0 0 0" axis="0 0 1" range="-2.618 2.618" actuatorfrcrange="-25 25" class="arm_motor" />
                    <geom type="mesh" mesh="left_shoulder_yaw_link" class="visual" />
                    <geom name="left_shoulder_yaw_link_collision" pos="0 0 0" quat="1.0 0.0 0.0 0.0" type="mesh" mesh="left_shoulder_yaw_link" class="left_arm_active" />

                    <body name="left_elbow_link" pos="0.015783 0 -0.080518" euler="0 1.0486 0">
                    <inertial pos="0.064956 0.004454 -0.010062" quat="0.541765 0.636132 0.388821 0.388129" mass="0.6" diaginertia="0.000443035 0.000421612 0.000259353" />
                    <joint name="left_elbow_joint" pos="0 0 0" axis="0 1 0" range="-1.57 1.57" actuatorfrcrange="-25 25" class="arm_motor" />
                    <geom type="mesh" mesh="left_elbow_link" class="visual" />
                    <geom name="left_elbow_link_collision" pos="0 0 0" quat="1.0 0.0 0.0 0.0" type="mesh" mesh="left_elbow_link" class="left_arm_active" />

                    <body name="left_wrist_roll_link" pos="0.1 0.00188791 -0.01">
                        <inertial pos="0.0171394 0.000537591 4.8864e-07" quat="0.575338 0.411667 -0.574906 0.411094" mass="0.085445" diaginertia="5.48211e-05 4.96646e-05 3.57798e-05" />
                        <joint name="left_wrist_roll_joint" pos="0 0 0" axis="1 0 0" range="-1.97222 1.97222" actuatorfrcrange="-25 25" class="arm_motor" />
                        <geom type="mesh" mesh="left_wrist_roll_link" class="visual" />
                        <geom name="left_wrist_roll_link_collision" pos="0 0 0" quat="1.0 0.0 0.0 0.0" type="mesh" mesh="left_wrist_roll_link" class="left_arm_active" />

                        <body name="left_wrist_pitch_link" pos="0.038 0 0">
                        <inertial pos="0.0229999 -0.00111685 -0.00111658" quat="0.249998 0.661363 0.293036 0.643608" mass="0.48405" diaginertia="0.000430353 0.000429873 0.000164648" />
                        <joint name="left_wrist_pitch_joint" pos="0 0 0" axis="0 1 0" range="-1.61443 1.61443" actuatorfrcrange="-5 5" class="wrist_motor" />
                        <geom type="mesh" mesh="left_wrist_pitch_link" class="visual" />
                        <geom name="left_wrist_pitch_link_collision" pos="0 0 0" quat="1.0 0.0 0.0 0.0" type="mesh" mesh="left_wrist_pitch_link" class="left_arm_active" />

                        <body name="left_wrist_yaw_link" pos="0.046 0 0">
                            <inertial pos="0.0708244 0.000191745 0.00161742" quat="0.510571 0.526295 0.468078 0.493188" mass="0.254576" diaginertia="0.000646113 0.000559993 0.000147566" />
                            <joint name="left_wrist_yaw_joint" pos="0 0 0" axis="0 0 1" range="-1.61443 1.61443" actuatorfrcrange="-5 5" class="wrist_motor" />
                            <geom type="mesh" mesh="left_wrist_yaw_link" class="visual" />
                            <geom name="left_wrist_yaw_link_collision" pos="0 0 0" quat="1.0 0.0 0.0 0.0" type="mesh" mesh="left_wrist_yaw_link" class="left_arm_active" />

                            <!-- ================= HAND MOUNT ================= -->
                            <body name="inhand_mount"
                                pos="0.04 0.002 0"
                                euler="0 1.57 3.1415926">

                            <!-- ================= PALM (TF base_link 对应的“手掌frame”) ================= -->
                            <body name="inhand_base_link">
                                <inertial pos="-0.00013 -0.00373 0.08269"
                                        quat="1 0 0 0"
                                        mass="0.62266"
                                        diaginertia="0.00022 0.00026 0.00013"/>

                                <geom type="mesh" mesh="inhand_base_link" class="visual"/>
                                <geom type="mesh" mesh="inhand_base_link" class="left_arm_active"/>

                                <site name="ee_site"
                                    pos="0 0.02 0.12"
                                    size="0.006"
                                    type="sphere"
                                    rgba="1 0 0 1"/>


                                <body name="left_thumb_1"
                                    pos="0.027 0.021 0.069"
                                    quat="1 0 0 0">
                                <geom type="mesh" mesh="inhand_left_thumb_1" class="visual"/>
                                <geom type="mesh" mesh="inhand_left_thumb_1" class="left_arm_active"/>


                                <body name="left_thumb_2"
                                        pos="0.007 0.011 0.005"
                                        quat="-0.092 -0.092 0.701 0.701">
                                    <geom type="mesh" mesh="inhand_left_thumb_2" class="visual"/>
                                    <geom type="mesh" mesh="inhand_left_thumb_2" class="left_arm_active"/>

                                    <body name="left_thumb_3" pos="-0.031 0.021 -0.001">
                                    <geom type="mesh" mesh="inhand_left_thumb_3" class="visual"/>
                                    <geom type="mesh" mesh="inhand_left_thumb_3" class="left_arm_active"/>

                                    <body name="left_thumb_4" pos="-0.022 0.013 0">
                                        <geom type="mesh" mesh="inhand_left_thumb_4" class="visual"/>
                                        <geom type="mesh" mesh="inhand_left_thumb_4" class="left_arm_active"/>
                                    </body>
                                    </body>
                                </body>
                                </body>

                                <body name="left_index_1"
                                    pos="0.039 0.001 0.156"
                                    quat="0.509 0.491 -0.491 -0.509">
                                <geom type="mesh" mesh="inhand_left_index_1" class="visual"/>
                                <geom type="mesh" mesh="inhand_left_index_1" class="left_arm_active"/>

                                <body name="left_index_2" pos="-0.003 0.033 0.001">
                                    <geom type="mesh" mesh="inhand_left_index_2" class="visual"/>
                                    <geom type="mesh" mesh="inhand_left_index_2" class="left_arm_active"/>
                                </body>
                                </body>


                                <body name="left_middle_1"
                                    pos="0.017 0.001 0.157"
                                    quat="-0.500 -0.500 0.500 0.500">
                                <geom type="mesh" mesh="inhand_left_middle_1" class="visual"/>
                                <geom type="mesh" mesh="inhand_left_middle_1" class="left_arm_active"/>

                                <body name="left_middle_2" pos="-0.003 0.033 0.001">
                                    <geom type="mesh" mesh="inhand_left_middle_2" class="visual"/>
                                    <geom type="mesh" mesh="inhand_left_middle_2" class="left_arm_active"/>
                                </body>
                                </body>


                                <body name="left_ring_1"
                                    pos="-0.005 0.001 0.157"
                                    quat="-0.487 -0.513 0.513 0.487">
                                <geom type="mesh" mesh="inhand_left_ring_1" class="visual"/>
                                <geom type="mesh" mesh="inhand_left_ring_1" class="left_arm_active"/>

                                <body name="left_ring_2" pos="-0.003 0.033 0.001">
                                    <geom type="mesh" mesh="inhand_left_ring_2" class="visual"/>
                                    <geom type="mesh" mesh="inhand_left_ring_2" class="left_arm_active"/>
                                </body>
                                </body>


                                <body name="left_little_1"
                                    pos="-0.026 0.001 0.154"
                                    quat="-0.473 -0.525 0.525 0.473">
                                <geom type="mesh" mesh="inhand_left_little_1" class="visual"/>
                                <geom type="mesh" mesh="inhand_left_little_1" class="left_arm_active"/>

                                <body name="left_little_2" pos="-0.003 0.033 0.001">
                                    <geom type="mesh" mesh="inhand_left_little_2" class="visual"/>
                                    <geom type="mesh" mesh="inhand_left_little_2" class="left_arm_active"/>
                                </body>
                                </body>

                            </body> 
                            </body> 

                        </body>
                        </body>
                    </body>
                    </body>
                </body>
                </body>
            </body>
            <body name="right_shoulder_pitch_link" pos="0.0039563 -0.10021 0.23778"
              quat="0.990264 -0.139201 1.38722e-05 9.86868e-05">
              <inertial pos="0 -0.035892 -0.011628" quat="0.68225 -0.326267 0.0130458 0.654152"
                mass="0.718" diaginertia="0.000465864 0.000432842 0.000406394" />
              <geom type="mesh" contype="0" conaffinity="0" group="1" density="0"
                rgba="0.7 0.7 0.7 1" mesh="right_shoulder_pitch_link" />
              <geom size="0.03 0.025" pos="0 -0.04 -0.01" quat="0.707107 0 0.707107 0"
                type="cylinder" rgba="0.7 0.7 0.7 1" class="base_static"/>
              <body name="right_shoulder_roll_link" pos="0 -0.038 -0.013831"
                quat="0.9994 0.0349 0 0">
                <inertial pos="-0.000227 -0.00727 -0.063243"
                  quat="0.712604 -0.00710317 -0.0196223 0.701256" mass="0.643"
                  diaginertia="0.000691311 0.000618011 0.000388977" />
                <geom type="mesh" contype="0" conaffinity="0" group="1" density="0"
                  rgba="0.7 0.7 0.7 1" mesh="right_shoulder_roll_link" />
                <geom size="0.03 0.015" pos="-0.004 -0.006 -0.053" type="cylinder"
                  rgba="0.7 0.7 0.7 1" class="base_static"/>
                <body name="right_shoulder_yaw_link" pos="0 -0.00624 -0.1032">
                  <inertial pos="0.010773 0.002949 -0.072009"
                    quat="0.687134 -0.0679942 -0.0964829 0.716879" mass="0.734"
                    diaginertia="0.00106187 0.00103217 0.000400661" />
                  <geom type="mesh" contype="0" conaffinity="0" group="1" density="0"
                    rgba="0.7 0.7 0.7 1" mesh="right_shoulder_yaw_link" />
                  <geom type="mesh" rgba="0.7 0.7 0.7 1" mesh="right_shoulder_yaw_link" class="base_static"/>
                  <body name="right_elbow_link" pos="0.015783 0 -0.080518" euler="0 1.0486 0">
                    <inertial pos="0.064956 -0.004454 -0.010062"
                      quat="0.388129 0.388821 0.636132 0.541765" mass="0.6"
                      diaginertia="0.000443035 0.000421612 0.000259353" />
                    <geom type="mesh" contype="0" conaffinity="0" group="1" density="0"
                      rgba="0.7 0.7 0.7 1" mesh="right_elbow_link" />
                    <geom type="mesh" rgba="0.7 0.7 0.7 1" mesh="right_elbow_link" class="base_static"/>
                    <body name="right_wrist_roll_link" pos="0.1 -0.00188791 -0.01">
                      <inertial pos="0.0171394 -0.000537591 4.8864e-07"
                        quat="0.411667 0.575338 -0.411094 0.574906" mass="0.085445"
                        diaginertia="5.48211e-05 4.96646e-05 3.57798e-05" />
                      <geom type="mesh" contype="0" conaffinity="0" group="1" density="0"
                        rgba="0.7 0.7 0.7 1" mesh="right_wrist_roll_link" />
                      <geom type="mesh" rgba="0.7 0.7 0.7 1" mesh="right_wrist_roll_link" class="base_static"/>
                      <body name="right_wrist_pitch_link" pos="0.038 0 0">
                        <inertial pos="0.0229999 0.00111685 -0.00111658"
                          quat="0.643608 0.293036 0.661363 0.249998" mass="0.48405"
                          diaginertia="0.000430353 0.000429873 0.000164648" />
                        <geom type="mesh" contype="0" conaffinity="0" group="1" density="0"
                          rgba="0.7 0.7 0.7 1" mesh="right_wrist_pitch_link" />
                        <geom type="mesh" rgba="0.7 0.7 0.7 1" mesh="right_wrist_pitch_link" class="base_static"/>
                        <body name="right_wrist_yaw_link" pos="0.046 0 0">
                          <inertial pos="0.0708244 -0.000191745 0.00161742"
                            quat="0.493188 0.468078 0.526295 0.510571" mass="0.254576"
                            diaginertia="0.000646113 0.000559993 0.000147566" />
                          <geom type="mesh" mesh="right_wrist_yaw_link" class="base_static" group="1" density="0" rgba="0.7 0.7 0.7 1" />
                          <geom pos="0.0415 -0.003 0" quat="1 0 0 0" type="mesh" mesh="right_rubber_hand" class="base_static" group="1" density="0" rgba="0.7 0.7 0.7 1" />
                        </body>
                      </body>
                    </body>
                  </body>
                </body>
              </body>
            </body>
          </body>
        </body>
      </body>
    </body>
  </worldbody>

  <actuator>
    <motor name="left_shoulder_pitch" joint="left_shoulder_pitch_joint" ctrlrange="-25 25" />
    <motor name="left_shoulder_roll" joint="left_shoulder_roll_joint" ctrlrange="-25 25" />
    <motor name="left_shoulder_yaw" joint="left_shoulder_yaw_joint" ctrlrange="-25 25" />
    <motor name="left_elbow" joint="left_elbow_joint" ctrlrange="-25 25" />
    <motor name="left_wrist_roll" joint="left_wrist_roll_joint" ctrlrange="-25 25" />
    <motor name="left_wrist_pitch" joint="left_wrist_pitch_joint" ctrlrange="-5 5" />
    <motor name="left_wrist_yaw" joint="left_wrist_yaw_joint" ctrlrange="-5 5" />
  </actuator>

  <contact>
    <exclude body1="left_shoulder_pitch_link" body2="left_shoulder_roll_link" />
    <exclude body1="left_shoulder_roll_link" body2="left_shoulder_yaw_link" />
    <exclude body1="left_shoulder_yaw_link" body2="left_elbow_link" />
    <exclude body1="left_elbow_link" body2="left_wrist_roll_link" />
    <exclude body1="left_wrist_roll_link" body2="left_wrist_pitch_link" />
    <exclude body1="left_wrist_pitch_link" body2="left_wrist_yaw_link" />
    <exclude body1="torso_link" body2="left_shoulder_roll_link" />
    <exclude body1="torso_link" body2="left_shoulder_pitch_link" />

  </contact>

</mujoco>
